<?xml version="1.0" encoding="utf-8"?>
<!-- =================================================================================== -->
<!-- |    This document was autogenerated by xacro from lab2_robot.xacro               | -->
<!-- |    EDITING THIS FILE BY HAND IS NOT RECOMMENDED                                 | -->
<!-- =================================================================================== -->
<robot name="lab2_robot">
  <!-- macros -->
  <material name="blue">
    <color rgba="0 0 0.9 1"/>
  </material>
  <!-- ROBOT BUILD STARTS HERE -->
  <link name="base_link">
    <visual>
      <geometry>
        <cylinder length="0.05" radius="0.05"/>
      </geometry>
      <origin xyz="0 0 0.025"/>
      <material name="blue"/>
    </visual>
  </link>
  <link name="link1">
    <visual>
      <geometry>
        <cylinder length="0" radius="0.05"/>
      </geometry>
      <origin rpy="0 0 0" xyz="0.0 0 0"/>
      <material name="blue"/>
    </visual>
  </link>
  <link name="link2">
    <visual>
      <geometry>
        <cylinder length="1" radius="0.05"/>
      </geometry>
      <origin rpy="0 0 0" xyz="0.5 0 0"/>
      <material name="blue"/>
    </visual>
  </link>
  <link name="link3">
    <visual>
      <geometry>
        <cylinder length="0.05" radius="0.02"/>
      </geometry>
      <origin rpy="0 0 0" xyz="0 0 0"/>
      <material name="blue"/>
    </visual>
  </link>
  <joint name="joint1" type="continuous">
    <parent link="base_link"/>
    <child link="link1"/>
    <origin rpy="0.0 -0.0 0.0" xyz="0.0 0.0 0.0"/>
    <axis xyz="0 0 1"/>
  </joint>
  <joint name="joint2" type="continuous">
    <parent link="link1"/>
    <child link="link2"/>
    <origin rpy="-1.57 -0.0 0.0" xyz="0.0 0.0 0.0"/>
    <axis xyz="0 0 1"/>
  </joint>
  <joint name="joint3" type="continuous">
    <parent link="link2"/>
    <child link="link3"/>
    <origin rpy="0.0 -0.0 0.0" xyz="1.0 0.0 0.0"/>
    <axis xyz="0 0 1"/>
  </joint>
</robot>

